Workbook

Sheet Workforce_Data
A1: Workforce_Record_ID | B1: Production_Date | C1: Batch_ID | D1: Product_ID | E1: Product_Name | F1: Production_Line | G1: Shift | H1: Operator_Team | I1: Shift_Hours | J1: Total_Workforce | K1: Skilled_Workers | L1: Unskilled_Workers | M1: Absent_Workers | N1: Present_Workers | O1: Overtime_Hours | P1: Downtime_Minutes | Q1: Production_Hours | R1: Labour_Hours | S1: Planned_Good_Qty_Units | T1: Actual_Output_Units | U1: Rejected_Qty_Units | V1: Accepted_Good_Qty_Units | W1: Actual_Productivity | X1: Benchmark_Records | Y1: Benchmark_Productivity | Z1: Workforce_Efficiency | AA1: Required_Labour_Hours | AB1: Effective_Hours_Per_Worker | AC1: Required_Workers | AD1: Manpower_Gap | AE1: Manpower_Status
A2: WF-0001 | B2: 45915 | C2: BAT-WF-00001 | D2: SF-P058 | E2: Honey Ball - Variant 3 | F2: Line-5 | G2: Afternoon | H2: Team-C | I2: 8 | J2: 23 | K2: 8 | L2: 15 | M2: 0 | N2: 23 | O2: 1 | P2: 18 | Q2: 7.7 | R2: 177.1 | S2: 24967 | T2: 21362 | U2: 318 | V2: 21044 | W2: =IFERROR(V2/R2,0) -> 118.82552 | X2: 114.15637 | Y2: 114.15637 | Z2: =IFERROR(W2/Y2,0) -> 1.0409014 | AA2: =IFERROR(S2/Y2,0) -> 218.70877 | AB2: =MAX(0.1,I2-(P2/60)) -> 7.7 | AC2: =IFERROR(CEILING(AA2/AB2,1),0) -> 29 | AD2: =AC2-N2 -> 6 | AE2: =IF(AD2>0,"Shortage",IF(AD2<0,"Surplus","Balanced")) -> Shortage
A3: WF-0002 | B3: 45917 | C3: BAT-WF-00002 | D3: SF-P038 | E3: Honey Ball - Variant 2 | F3: Line-1 | G3: Morning | H3: Team-D | I3: 8 | J3: 19 | K3: 7 | L3: 12 | M3: 0 | N3: 19 | O3: 3 | P3: 8 | Q3: 7.87 | R3: 149.53 | S3: 19721 | T3: 18079 | U3: 523 | V3: 17556 | W3: =IFERROR(V3/R3,0) -> 117.40788 | X3: 115.18556 | Y3: 115.18556 | Z3: =IFERROR(W3/Y3,0) -> 1.0192934 | AA3: =IFERROR(S3/Y3,0) -> 171.2107 | AB3: =MAX(0.1,I3-(P3/60)) -> 7.8666667 | AC3: =IFERROR(CEILING(AA3/AB3,1),0) -> 22 | AD3: =AC3-N3 -> 3 | AE3: =IF(AD3>0,"Shortage",IF(AD3<0,"Surplus","Balanced")) -> Shortage
A4: WF-0004 | B4: 45918 | C4: BAT-WF-00004 | D4: SF-P070 | E4: Muesli - Variant 4 | F4: Line-2 | G4: Morning | H4: Team-F | I4: 10 | J4: 25 | K4: 10 | L4: 15 | M4: 1 | N4: 24 | O4: 0 | P4: 55 | Q4: 9.08 | R4: 217.92 | S4: 23429 | T4: 17745 | U4: 340 | V4: 17405 | W4: =IFERROR(V4/R4,0) -> 79.868759 | X4: 124.7824 | Y4: 124.7824 | Z4: =IFERROR(W4/Y4,0) -> 0.6400643 | AA4: =IFERROR(S4/Y4,0) -> 187.75885 | AB4: =MAX(0.1,I4-(P4/60)) -> 9.0833333 | AC4: =IFERROR(CEILING(AA4/AB4,1),0) -> 21 | AD4: =AC4-N4 -> -3 | AE4: =IF(AD4>0,"Shortage",IF(AD4<0,"Surplus","Balanced")) -> Surplus
A5: WF-0005 | B5: 45918 | C5: BAT-WF-00005 | D5: SF-P099 | E5: Crispy Bites - Variant 5 | F5: Line-3 | G5: Morning | H5: Team-C | I5: 8 | J5: 17 | K5: 8 | L5: 9 | M5: 0 | N5: 17 | O5: 3 | P5: 39 | Q5: 7.35 | R5: 124.95 | S5: 16430 | T5: 12349 | U5: 270 | V5: 12079 | W5: =IFERROR(V5/R5,0) -> 96.670668 | X5: 109.38855 | Y5: 109.38855 | Z5: =IFERROR(W5/Y5,0) -> 0.8837366 | AA5: =IFERROR(S5/Y5,0) -> 150.19853 | AB5: =MAX(0.1,I5-(P5/60)) -> 7.35 | AC5: =IFERROR(CEILING(AA5/AB5,1),0) -> 21 | AD5: =AC5-N5 -> 4 | AE5: =IF(AD5>0,"Shortage",IF(AD5<0,"Surplus","Balanced")) -> Shortage
A6: WF-0003 | B6: 45918 | C6: BAT-WF-00003 | D6: SF-P060 | E6: Granola - Variant 3 | F6: Line-5 | G6: Morning | H6: Team-C | I6: 10 | J6: 24 | K6: 11 | L6: 13 | M6: 0 | N6: 24 | O6: 0 | P6: 35 | Q6: 9.42 | R6: 226.08 | S6: 20728 | T6: 18289 | U6: 352 | V6: 17937 | W6: =IFERROR(V6/R6,0) -> 79.339172 | X6: 118.01657 | Y6: 118.01657 | Z6: =IFERROR(W6/Y6,0) -> 0.67227149 | AA6: =IFERROR(S6/Y6,0) -> 175.63636 | AB6: =MAX(0.1,I6-(P6/60)) -> 9.4166667 | AC6: =IFERROR(CEILING(AA6/AB6,1),0) -> 19 | AD6: =AC6-N6 -> -5 | AE6: =IF(AD6>0,"Shortage",IF(AD6<0,"Surplus","Balanced")) -> Surplus
A7: WF-0008 | B7: 45919 | C7: BAT-WF-00008 | D7: SF-P034 | E7: Fruit Ball - Variant 2 | F7: Line-1 | G7: Afternoon | H7: Team-C | I7: 8 | J7: 19 | K7: 8 | L7: 11 | M7: 0 | N7: 19 | O7: 2 | P7: 35 | Q7: 7.42 | R7: 140.98 | S7: 19395 | T7: 15022 | U7: 231 | V7: 14791 | W7: =IFERROR(V7/R7,0) -> 104.91559 | X7: 112.98348 | Y7: 112.98348 | Z7: =IFERROR(W7/Y7,0) -> 0.92859234 | AA7: =IFERROR(S7/Y7,0) -> 171.66227 | AB7: =MAX(0.1,I7-(P7/60)) -> 7.4166667 | AC7: =IFERROR(CEILING(AA7/AB7,1),0) -> 24 | AD7: =AC7-N7 -> 5 | AE7: =IF(AD7>0,"Shortage",IF(AD7<0,"Surplus","Balanced")) -> Shortage
A8: WF-0007 | B8: 45919 | C8: BAT-WF-00007 | D8: SF-P030 | E8: Muesli - Variant 2 | F8: Line-4 | G8: Afternoon | H8: Team-E | I8: 8 | J8: 26 | K8: 10 | L8: 16 | M8: 0 | N8: 26 | O8: 2 | P8: 16 | Q8: 7.73 | R8: 200.98 | S8: 21768 | T8: 22188 | U8: 372 | V8: 21816 | W8: =IFERROR(V8/R8,0) -> 108.54811 | X8: 120.8175 | Y8: 120.8175 | Z8: =IFERROR(W8/Y8,0) -> 0.89844696 | AA8: =IFERROR(S8/Y8,0) -> 180.17258 | AB8: =MAX(0.1,I8-(P8/60)) -> 7.7333333 | AC8: =IFERROR(CEILING(AA8/AB8,1),0) -> 24 | AD8: =AC8-N8 -> -2 | AE8: =IF(AD8>0,"Shortage",IF(AD8<0,"Surplus","Balanced")) -> Surplus
A9: WF-0006 | B9: 45919 | C9: BAT-WF-00006 | D9: SF-P028 | E9: Jumbo Oats - Variant 2 | F9: Line-5 | G9: Morning | H9: Team-B | I9: 9 | J9: 22 | K9: 8 | L9: 14 | M9: 0 | N9: 22 | O9: 3 | P9: 48 | Q9: 8.2 | R9: 180.4 | S9: 21770 | T9: 15694 | U9: 220 | V9: 15474 | W9: =IFERROR(V9/R9,0) -> 85.776053 | X9: 118.01657 | Y9: 118.01657 | Z9: =IFERROR(W9/Y9,0) -> 0.72681367 | AA9: =IFERROR(S9/Y9,0) -> 184.46563 | AB9: =MAX(0.1,I9-(P9/60)) -> 8.2 | AC9: =IFERROR(CEILING(AA9/AB9,1),0) -> 23 | AD9: =AC9-N9 -> 1 | AE9: =IF(AD9>0,"Shortage",IF(AD9<0,"Surplus","Balanced")) -> Shortage
A10: WF-0009 | B10: 45919 | C10: BAT-WF-00009 | D10: SF-P032 | E10: Rice Crispy - Variant 2 | F10: Line-1 | G10: Night | H10: Team-F | I10: 8 | J10: 15 | K10: 7 | L10: 8 | M10: 1 | N10: 14 | O10: 0 | P10: 48 | Q10: 7.2 | R10: 100.8 | S10: 12207 | T10: 9767 | U10: 112 | V10: 9655 | W10: =IFERROR(V10/R10,0) -> 95.78373 | X10: 99.399923 | Y10: 99.399923 | Z10: =IFERROR(W10/Y10,0) -> 0.96361977 | AA10: =IFERROR(S10/Y10,0) -> 122.80694 | AB10: =MAX(0.1,I10-(P10/60)) -> 7.2 | AC10: =IFERROR(CEILING(AA10/AB10,1),0) -> 18 | AD10: =AC10-N10 -> 4 | AE10: =IF(AD10>0,"Shortage",IF(AD10<0,"Surplus","Balanced")) -> Shortage
A11: WF-0010 | B11: 45923 | C11: BAT-WF-00010 | D11: SF-P050 | E11: Muesli - Variant 3 | F11: Line-3 | G11: Morning | H11: Team-B | I11: 10 | J11: 21 | K11: 8 | L11: 13 | M11: 1 | N11: 20 | O11: 3 | P11: 26 | Q11: 9.57 | R11: 191.4 | S11: 18702 | T11: 16083 | U11: 86 | V11: 15997 | W11: =IFERROR(V11/R11,0) -> 83.578892 | X11: 109.38855 | Y11: 109.38855 | Z11: =IFERROR(W11/Y11,0) -> 0.7640552 | AA11: =IFERROR(S11/Y11,0) -> 170.96853 | AB11: =MAX(0.1,I11-(P11/60)) -> 9.5666667 | AC11: =IFERROR(CEILING(AA11/AB11,1),0) -> 18 | AD11: =AC11-N11 -> -2 | AE11: =IF(AD11>0,"Shortage",IF(AD11<0,"Surplus","Balanced")) -> Surplus
A12: WF-0011 | B12: 45923 | C12: BAT-WF-00011 | D12: SF-P053 | E12: Cocoa Rice Crispy - Variant 3 | F12: Line-3 | G12: Morning | H12: Team-A | I12: 10 | J12: 15 | K12: 5 | L12: 10 | M12: 0 | N12: 15 | O12: 2 | P12: 36 | Q12: 9.4 | R12: 141 | S12: 19264 | T12: 16603 | U12: 519 | V12: 16084 | W12: =IFERROR(V12/R12,0) -> 114.07092 | X12: 109.38855 | Y12: 109.38855 | Z12: =IFERROR(W12/Y12,0) -> 1.0428049 | AA12: =IFERROR(S12/Y12,0) -> 176.10618 | AB12: =MAX(0.1,I12-(P12/60)) -> 9.4 | AC12: =IFERROR(CEILING(AA12/AB12,1),0) -> 19 | AD12: =AC12-N12 -> 4 | AE12: =IF(AD12>0,"Shortage",IF(AD12<0,"Surplus","Balanced")) -> Shortage
A13: WF-0013 | B13: 45924 | C13: BAT-WF-00013 | D13: SF-P058 | E13: Honey Ball - Variant 3 | F13: Line-2 | G13: Afternoon | H13: Team-B | I13: 9 | J13: 23 | K13: 7 | L13: 16 | M13: 0 | N13: 23 | O13: 0 | P13: 48 | Q13: 8.2 | R13: 188.6 | S13: 27427 | T13: 20576 | U13: 723 | V13: 19853 | W13: =IFERROR(V13/R13,0) -> 105.26511 | X13: 118.40848 | Y13: 118.40848 | Z13: =IFERROR(W13/Y13,0) -> 0.88899978 | AA13: =IFERROR(S13/Y13,0) -> 231.63037 | AB13: =MAX(0.1,I13-(P13/60)) -> 8.2 | AC13: =IFERROR(CEILING(AA13/AB13,1),0) -> 29 | AD13: =AC13-N13 -> 6 | AE13: =IF(AD13>0,"Shortage",IF(AD13<0,"Surplus","Balanced")) -> Shortage
... A501: WF-0500 | B501: 46279 | C501: BAT-WF-00500 | D501: SF-P095 | E501: Coated Crispy Choco Balls - Variant 5 | F501: Line-4 | G501: Afternoon | H501: Team-E | I501: 8 | J501: 28 | K501: 12 | L501: 16 | M501: 0 | N501: 28 | O501: 0 | P501: 58 | Q501: 7.03 | R501: 196.84 | S501: 33796 | T501: 25305 | U501: 485 | V501: 24820 | W501: =IFERROR(V501/R501,0) -> 126.09226 | X501: 120.8175 | Y501: 120.8175 | Z501: =IFERROR(W501/Y501,0) -> 1.0436589 | AA501: =IFERROR(S501/Y501,0) -> 279.72769 | AB501: =MAX(0.1,I501-(P501/60)) -> 7.0333333 | AC501: =IFERROR(CEILING(AA501/AB501,1),0) -> 40 | AD501: =AC501-N501 -> 12 | AE501: =IF(AD501>0,"Shortage",IF(AD501<0,"Surplus","Balanced")) -> Shortage

Sheet Methodology
A1: WORKFORCE EFFICIENCY & MANPOWER PLANNING — METHODOLOGY
A3: Metric | B3: Definition
A4: Business question | B4: How many workers are required to produce a planned quantity efficiently?
A5: Productivity | B5: Accepted Good Qty ÷ Labour Hours
A6: Benchmark | B6: 75th percentile historical productivity by Production Line + Shift
A7: Workforce efficiency | B7: Actual Productivity ÷ Benchmark Productivity
A8: Effective hours | B8: Shift Hours − expected/observed downtime
A9: Required labour hours | B9: Planned Good Qty ÷ Benchmark Productivity
A10: Required workers | B10: Required Labour Hours ÷ Effective Hours per Worker, rounded up
A11: Manpower gap | B11: Required Workers − Present Workers
A12: Decision | B12: Positive gap = shortage; negative gap = surplus; zero = balanced
A13: Important | B13: Current dataset is synthetic/illustrative; replace with real company history before operational decisions.

Sheet Benchmark_Master
A1: Production_Line | B1: Shift | C1: Records | D1: Benchmark_Productivity | E1: Avg_Downtime_Minutes | F1: Key
A2: Line-1 | B2: Afternoon | C2: 38 | D2: 112.98348 | E2: 32.184211 | F2: Line-1|Afternoon
A3: Line-1 | B3: Morning | C3: 53 | D3: 115.18556 | E3: 34.283019 | F3: Line-1|Morning
A4: Line-1 | B4: Night | C4: 17 | D4: 99.399923 | E4: 33.470588 | F4: Line-1|Night
A5: Line-2 | B5: Afternoon | C5: 37 | D5: 118.40848 | E5: 35.594595 | F5: Line-2|Afternoon
A6: Line-2 | B6: Morning | C6: 44 | D6: 124.7824 | E6: 31.795455 | F6: Line-2|Morning
A7: Line-2 | B7: Night | C7: 16 | D7: 107.36289 | E7: 38.6875 | F7: Line-2|Night
A8: Line-3 | B8: Afternoon | C8: 43 | D8: 108.32817 | E8: 31.813953 | F8: Line-3|Afternoon
A9: Line-3 | B9: Morning | C9: 52 | D9: 109.38855 | E9: 31.230769 | F9: Line-3|Morning
A10: Line-3 | B10: Night | C10: 19 | D10: 99.520306 | E10: 38.105263 | F10: Line-3|Night
A11: Line-4 | B11: Afternoon | C11: 28 | D11: 120.8175 | E11: 25.5 | F11: Line-4|Afternoon
A12: Line-4 | B12: Morning | C12: 34 | D12: 128.22014 | E12: 33.941176 | F12: Line-4|Morning
A13: Line-4 | B13: Night | C13: 18 | D13: 114.65795 | E13: 28.166667 | F13: Line-4|Night
... A16: Line-5 | B16: Night | C16: 10 | D16: 100.66501 | E16: 34.4 | F16: Line-5|Night

Sheet Historical_Summary
A1: WORKFORCE EFFICIENCY — HISTORICAL SUMMARY
A3: Production_Line | B3: Shift | C3: Records | D3: Avg_Productivity | E3: Benchmark_P75 | F3: Avg_Efficiency | G3: Avg_Present_Workers | H3: Avg_Required_Workers | I3: Avg_Gap | J3: Shortage_Obs | K3: Surplus_Obs
A4: Line-1 | B4: Afternoon | C4: =COUNTIFS(Workforce_Data!$F:$F,$A4,Workforce_Data!$G:$G,$B4) -> 38 | D4: =IFERROR(AVERAGEIFS(Workforce_Data!$W$2:$W$501,Workforce_Data!$F$2:$F$501,A4,Workforce_Data!$G$2:$G$501,B4),0) -> 104.49016 | E4: 112.98348 | F4: =IFERROR(AVERAGEIFS(Workforce_Data!$Z$2:$Z$501,Workforce_Data!$F$2:$F$501,A4,Workforce_Data!$G$2:$G$501,B4),0) -> 0.92482692 | G4: =IFERROR(AVERAGEIFS(Workforce_Data!$N$2:$N$501,Workforce_Data!$F$2:$F$501,A4,Workforce_Data!$G$2:$G$501,B4),0) -> 17.5 | H4: =IFERROR(AVERAGEIFS(Workforce_Data!$AC$2:$AC$501,Workforce_Data!$F$2:$F$501,A4,Workforce_Data!$G$2:$G$501,B4),0) -> 19.631579 | I4: =IFERROR(AVERAGEIFS(Workforce_Data!$AD$2:$AD$501,Workforce_Data!$F$2:$F$501,A4,Workforce_Data!$G$2:$G$501,B4),0) -> 2.1315789 | J4: =COUNTIFS(Workforce_Data!$F$2:$F$501,A4,Workforce_Data!$G$2:$G$501,B4,Workforce_Data!$AD$2:$AD$501,">0") -> 31 | K4: =COUNTIFS(Workforce_Data!$F$2:$F$501,A4,Workforce_Data!$G$2:$G$501,B4,Workforce_Data!$AD$2:$AD$501,"<0") -> 6
A5: Line-1 | B5: Morning | C5: =COUNTIFS(Workforce_Data!$F:$F,$A5,Workforce_Data!$G:$G,$B5) -> 53 | D5: =IFERROR(AVERAGEIFS(Workforce_Data!$W$2:$W$501,Workforce_Data!$F$2:$F$501,A5,Workforce_Data!$G$2:$G$501,B5),0) -> 107.06133 | E5: 115.18556 | F5: =IFERROR(AVERAGEIFS(Workforce_Data!$Z$2:$Z$501,Workforce_Data!$F$2:$F$501,A5,Workforce_Data!$G$2:$G$501,B5),0) -> 0.92946837 | G5: =IFERROR(AVERAGEIFS(Workforce_Data!$N$2:$N$501,Workforce_Data!$F$2:$F$501,A5,Workforce_Data!$G$2:$G$501,B5),0) -> 19.622642 | H5: =IFERROR(AVERAGEIFS(Workforce_Data!$AC$2:$AC$501,Workforce_Data!$F$2:$F$501,A5,Workforce_Data!$G$2:$G$501,B5),0) -> 22.54717 | I5: =IFERROR(AVERAGEIFS(Workforce_Data!$AD$2:$AD$501,Workforce_Data!$F$2:$F$501,A5,Workforce_Data!$G$2:$G$501,B5),0) -> 2.9245283 | J5: =COUNTIFS(Workforce_Data!$F$2:$F$501,A5,Workforce_Data!$G$2:$G$501,B5,Workforce_Data!$AD$2:$AD$501,">0") -> 47 | K5: =COUNTIFS(Workforce_Data!$F$2:$F$501,A5,Workforce_Data!$G$2:$G$501,B5,Workforce_Data!$AD$2:$AD$501,"<0") -> 5
A6: Line-1 | B6: Night | C6: =COUNTIFS(Workforce_Data!$F:$F,$A6,Workforce_Data!$G:$G,$B6) -> 17 | D6: =IFERROR(AVERAGEIFS(Workforce_Data!$W$2:$W$501,Workforce_Data!$F$2:$F$501,A6,Workforce_Data!$G$2:$G$501,B6),0) -> 94.588592 | E6: 99.399923 | F6: =IFERROR(AVERAGEIFS(Workforce_Data!$Z$2:$Z$501,Workforce_Data!$F$2:$F$501,A6,Workforce_Data!$G$2:$G$501,B6),0) -> 0.95159623 | G6: =IFERROR(AVERAGEIFS(Workforce_Data!$N$2:$N$501,Workforce_Data!$F$2:$F$501,A6,Workforce_Data!$G$2:$G$501,B6),0) -> 14.647059 | H6: =IFERROR(AVERAGEIFS(Workforce_Data!$AC$2:$AC$501,Workforce_Data!$F$2:$F$501,A6,Workforce_Data!$G$2:$G$501,B6),0) -> 17.529412 | I6: =IFERROR(AVERAGEIFS(Workforce_Data!$AD$2:$AD$501,Workforce_Data!$F$2:$F$501,A6,Workforce_Data!$G$2:$G$501,B6),0) -> 2.8823529 | J6: =COUNTIFS(Workforce_Data!$F$2:$F$501,A6,Workforce_Data!$G$2:$G$501,B6,Workforce_Data!$AD$2:$AD$501,">0") -> 16 | K6: =COUNTIFS(Workforce_Data!$F$2:$F$501,A6,Workforce_Data!$G$2:$G$501,B6,Workforce_Data!$AD$2:$AD$501,"<0") -> 1
A7: Line-2 | B7: Afternoon | C7: =COUNTIFS(Workforce_Data!$F:$F,$A7,Workforce_Data!$G:$G,$B7) -> 37 | D7: =IFERROR(AVERAGEIFS(Workforce_Data!$W$2:$W$501,Workforce_Data!$F$2:$F$501,A7,Workforce_Data!$G$2:$G$501,B7),0) -> 109.25779 | E7: 118.40848 | F7: =IFERROR(AVERAGEIFS(Workforce_Data!$Z$2:$Z$501,Workforce_Data!$F$2:$F$501,A7,Workforce_Data!$G$2:$G$501,B7),0) -> 0.92271934 | G7: =IFERROR(AVERAGEIFS(Workforce_Data!$N$2:$N$501,Workforce_Data!$F$2:$F$501,A7,Workforce_Data!$G$2:$G$501,B7),0) -> 20.810811 | H7: =IFERROR(AVERAGEIFS(Workforce_Data!$AC$2:$AC$501,Workforce_Data!$F$2:$F$501,A7,Workforce_Data!$G$2:$G$501,B7),0) -> 23.486486 | I7: =IFERROR(AVERAGEIFS(Workforce_Data!$AD$2:$AD$501,Workforce_Data!$F$2:$F$501,A7,Workforce_Data!$G$2:$G$501,B7),0) -> 2.6756757 | J7: =COUNTIFS(Workforce_Data!$F$2:$F$501,A7,Workforce_Data!$G$2:$G$501,B7,Workforce_Data!$AD$2:$AD$501,">0") -> 31 | K7: =COUNTIFS(Workforce_Data!$F$2:$F$501,A7,Workforce_Data!$G$2:$G$501,B7,Workforce_Data!$AD$2:$AD$501,"<0") -> 6
A8: Line-2 | B8: Morning | C8: =COUNTIFS(Workforce_Data!$F:$F,$A8,Workforce_Data!$G:$G,$B8) -> 44 | D8: =IFERROR(AVERAGEIFS(Workforce_Data!$W$2:$W$501,Workforce_Data!$F$2:$F$501,A8,Workforce_Data!$G$2:$G$501,B8),0) -> 115.9386 | E8: 124.7824 | F8: =IFERROR(AVERAGEIFS(Workforce_Data!$Z$2:$Z$501,Workforce_Data!$F$2:$F$501,A8,Workforce_Data!$G$2:$G$501,B8),0) -> 0.92912619 | G8: =IFERROR(AVERAGEIFS(Workforce_Data!$N$2:$N$501,Workforce_Data!$F$2:$F$501,A8,Workforce_Data!$G$2:$G$501,B8),0) -> 23.454545 | H8: =IFERROR(AVERAGEIFS(Workforce_Data!$AC$2:$AC$501,Workforce_Data!$F$2:$F$501,A8,Workforce_Data!$G$2:$G$501,B8),0) -> 26.113636 | I8: =IFERROR(AVERAGEIFS(Workforce_Data!$AD$2:$AD$501,Workforce_Data!$F$2:$F$501,A8,Workforce_Data!$G$2:$G$501,B8),0) -> 2.6590909 | J8: =COUNTIFS(Workforce_Data!$F$2:$F$501,A8,Workforce_Data!$G$2:$G$501,B8,Workforce_Data!$AD$2:$AD$501,">0") -> 37 | K8: =COUNTIFS(Workforce_Data!$F$2:$F$501,A8,Workforce_Data!$G$2:$G$501,B8,Workforce_Data!$AD$2:$AD$501,"<0") -> 6
A9: Line-2 | B9: Night | C9: =COUNTIFS(Workforce_Data!$F:$F,$A9,Workforce_Data!$G:$G,$B9) -> 16 | D9: =IFERROR(AVERAGEIFS(Workforce_Data!$W$2:$W$501,Workforce_Data!$F$2:$F$501,A9,Workforce_Data!$G$2:$G$501,B9),0) -> 97.663956 | E9: 107.36289 | F9: =IFERROR(AVERAGEIFS(Workforce_Data!$Z$2:$Z$501,Workforce_Data!$F$2:$F$501,A9,Workforce_Data!$G$2:$G$501,B9),0) -> 0.90966212 | G9: =IFERROR(AVERAGEIFS(Workforce_Data!$N$2:$N$501,Workforce_Data!$F$2:$F$501,A9,Workforce_Data!$G$2:$G$501,B9),0) -> 19.3125 | H9: =IFERROR(AVERAGEIFS(Workforce_Data!$AC$2:$AC$501,Workforce_Data!$F$2:$F$501,A9,Workforce_Data!$G$2:$G$501,B9),0) -> 20.9375 | I9: =IFERROR(AVERAGEIFS(Workforce_Data!$AD$2:$AD$501,Workforce_Data!$F$2:$F$501,A9,Workforce_Data!$G$2:$G$501,B9),0) -> 1.625 | J9: =COUNTIFS(Workforce_Data!$F$2:$F$501,A9,Workforce_Data!$G$2:$G$501,B9,Workforce_Data!$AD$2:$AD$501,">0") -> 9 | K9: =COUNTIFS(Workforce_Data!$F$2:$F$501,A9,Workforce_Data!$G$2:$G$501,B9,Workforce_Data!$AD$2:$AD$501,"<0") -> 6
A10: Line-3 | B10: Afternoon | C10: =COUNTIFS(Workforce_Data!$F:$F,$A10,Workforce_Data!$G:$G,$B10) -> 43 | D10: =IFERROR(AVERAGEIFS(Workforce_Data!$W$2:$W$501,Workforce_Data!$F$2:$F$501,A10,Workforce_Data!$G$2:$G$501,B10),0) -> 98.124781 | E10: 108.32817 | F10: =IFERROR(AVERAGEIFS(Workforce_Data!$Z$2:$Z$501,Workforce_Data!$F$2:$F$501,A10,Workforce_Data!$G$2:$G$501,B10),0) -> 0.90581036 | G10: =IFERROR(AVERAGEIFS(Workforce_Data!$N$2:$N$501,Workforce_Data!$F$2:$F$501,A10,Workforce_Data!$G$2:$G$501,B10),0) -> 15.813953 | H10: =IFERROR(AVERAGEIFS(Workforce_Data!$AC$2:$AC$501,Workforce_Data!$F$2:$F$501,A10,Workforce_Data!$G$2:$G$501,B10),0) -> 17.395349 | I10: =IFERROR(AVERAGEIFS(Workforce_Data!$AD$2:$AD$501,Workforce_Data!$F$2:$F$501,A10,Workforce_Data!$G$2:$G$501,B10),0) -> 1.5813953 | J10: =COUNTIFS(Workforce_Data!$F$2:$F$501,A10,Workforce_Data!$G$2:$G$501,B10,Workforce_Data!$AD$2:$AD$501,">0") -> 32 | K10: =COUNTIFS(Workforce_Data!$F$2:$F$501,A10,Workforce_Data!$G$2:$G$501,B10,Workforce_Data!$AD$2:$AD$501,"<0") -> 6
A11: Line-3 | B11: Morning | C11: =COUNTIFS(Workforce_Data!$F:$F,$A11,Workforce_Data!$G:$G,$B11) -> 52 | D11: =IFERROR(AVERAGEIFS(Workforce_Data!$W$2:$W$501,Workforce_Data!$F$2:$F$501,A11,Workforce_Data!$G$2:$G$501,B11),0) -> 100.66192 | E11: 109.38855 | F11: =IFERROR(AVERAGEIFS(Workforce_Data!$Z$2:$Z$501,Workforce_Data!$F$2:$F$501,A11,Workforce_Data!$G$2:$G$501,B11),0) -> 0.92022357 | G11: =IFERROR(AVERAGEIFS(Workforce_Data!$N$2:$N$501,Workforce_Data!$F$2:$F$501,A11,Workforce_Data!$G$2:$G$501,B11),0) -> 17.365385 | H11: =IFERROR(AVERAGEIFS(Workforce_Data!$AC$2:$AC$501,Workforce_Data!$F$2:$F$501,A11,Workforce_Data!$G$2:$G$501,B11),0) -> 19.038462 | I11: =IFERROR(AVERAGEIFS(Workforce_Data!$AD$2:$AD$501,Workforce_Data!$F$2:$F$501,A11,Workforce_Data!$G$2:$G$501,B11),0) -> 1.6730769 | J11: =COUNTIFS(Workforce_Data!$F$2:$F$501,A11,Workforce_Data!$G$2:$G$501,B11,Workforce_Data!$AD$2:$AD$501,">0") -> 41 | K11: =COUNTIFS(Workforce_Data!$F$2:$F$501,A11,Workforce_Data!$G$2:$G$501,B11,Workforce_Data!$AD$2:$AD$501,"<0") -> 7
A12: Line-3 | B12: Night | C12: =COUNTIFS(Workforce_Data!$F:$F,$A12,Workforce_Data!$G:$G,$B12) -> 19 | D12: =IFERROR(AVERAGEIFS(Workforce_Data!$W$2:$W$501,Workforce_Data!$F$2:$F$501,A12,Workforce_Data!$G$2:$G$501,B12),0) -> 90.219841 | E12: 99.520306 | F12: =IFERROR(AVERAGEIFS(Workforce_Data!$Z$2:$Z$501,Workforce_Data!$F$2:$F$501,A12,Workforce_Data!$G$2:$G$501,B12),0) -> 0.90654707 | G12: =IFERROR(AVERAGEIFS(Workforce_Data!$N$2:$N$501,Workforce_Data!$F$2:$F$501,A12,Workforce_Data!$G$2:$G$501,B12),0) -> 12.789474 | H12: =IFERROR(AVERAGEIFS(Workforce_Data!$AC$2:$AC$501,Workforce_Data!$F$2:$F$501,A12,Workforce_Data!$G$2:$G$501,B12),0) -> 14.157895 | I12: =IFERROR(AVERAGEIFS(Workforce_Data!$AD$2:$AD$501,Workforce_Data!$F$2:$F$501,A12,Workforce_Data!$G$2:$G$501,B12),0) -> 1.3684211 | J12: =COUNTIFS(Workforce_Data!$F$2:$F$501,A12,Workforce_Data!$G$2:$G$501,B12,Workforce_Data!$AD$2:$AD$501,">0") -> 16 | K12: =COUNTIFS(Workforce_Data!$F$2:$F$501,A12,Workforce_Data!$G$2:$G$501,B12,Workforce_Data!$AD$2:$AD$501,"<0") -> 2
A13: Line-4 | B13: Afternoon | C13: =COUNTIFS(Workforce_Data!$F:$F,$A13,Workforce_Data!$G:$G,$B13) -> 28 | D13: =IFERROR(AVERAGEIFS(Workforce_Data!$W$2:$W$501,Workforce_Data!$F$2:$F$501,A13,Workforce_Data!$G$2:$G$501,B13),0) -> 111.57826 | E13: 120.8175 | F13: =IFERROR(AVERAGEIFS(Workforce_Data!$Z$2:$Z$501,Workforce_Data!$F$2:$F$501,A13,Workforce_Data!$G$2:$G$501,B13),0) -> 0.92352729 | G13: =IFERROR(AVERAGEIFS(Workforce_Data!$N$2:$N$501,Workforce_Data!$F$2:$F$501,A13,Workforce_Data!$G$2:$G$501,B13),0) -> 24.678571 | H13: =IFERROR(AVERAGEIFS(Workforce_Data!$AC$2:$AC$501,Workforce_Data!$F$2:$F$501,A13,Workforce_Data!$G$2:$G$501,B13),0) -> 28.357143 | I13: =IFERROR(AVERAGEIFS(Workforce_Data!$AD$2:$AD$501,Workforce_Data!$F$2:$F$501,A13,Workforce_Data!$G$2:$G$501,B13),0) -> 3.6785714 | J13: =COUNTIFS(Workforce_Data!$F$2:$F$501,A13,Workforce_Data!$G$2:$G$501,B13,Workforce_Data!$AD$2:$AD$501,">0") -> 23 | K13: =COUNTIFS(Workforce_Data!$F$2:$F$501,A13,Workforce_Data!$G$2:$G$501,B13,Workforce_Data!$AD$2:$AD$501,"<0") -> 5
A14: Line-4 | B14: Morning | C14: =COUNTIFS(Workforce_Data!$F:$F,$A14,Workforce_Data!$G:$G,$B14) -> 34 | D14: =IFERROR(AVERAGEIFS(Workforce_Data!$W$2:$W$501,Workforce_Data!$F$2:$F$501,A14,Workforce_Data!$G$2:$G$501,B14),0) -> 119.40702 | E14: 128.22014 | F14: =IFERROR(AVERAGEIFS(Workforce_Data!$Z$2:$Z$501,Workforce_Data!$F$2:$F$501,A14,Workforce_Data!$G$2:$G$501,B14),0) -> 0.93126569 | G14: =IFERROR(AVERAGEIFS(Workforce_Data!$N$2:$N$501,Workforce_Data!$F$2:$F$501,A14,Workforce_Data!$G$2:$G$501,B14),0) -> 26.529412 | H14: =IFERROR(AVERAGEIFS(Workforce_Data!$AC$2:$AC$501,Workforce_Data!$F$2:$F$501,A14,Workforce_Data!$G$2:$G$501,B14),0) -> 30.235294 | I14: =IFERROR(AVERAGEIFS(Workforce_Data!$AD$2:$AD$501,Workforce_Data!$F$2:$F$501,A14,Workforce_Data!$G$2:$G$501,B14),0) -> 3.7058824 | J14: =COUNTIFS(Workforce_Data!$F$2:$F$501,A14,Workforce_Data!$G$2:$G$501,B14,Workforce_Data!$AD$2:$AD$501,">0") -> 30 | K14: =COUNTIFS(Workforce_Data!$F$2:$F$501,A14,Workforce_Data!$G$2:$G$501,B14,Workforce_Data!$AD$2:$AD$501,"<0") -> 2
A15: Line-4 | B15: Night | C15: =COUNTIFS(Workforce_Data!$F:$F,$A15,Workforce_Data!$G:$G,$B15) -> 18 | D15: =IFERROR(AVERAGEIFS(Workforce_Data!$W$2:$W$501,Workforce_Data!$F$2:$F$501,A15,Workforce_Data!$G$2:$G$501,B15),0) -> 109.44237 | E15: 114.65795 | F15: =IFERROR(AVERAGEIFS(Workforce_Data!$Z$2:$Z$501,Workforce_Data!$F$2:$F$501,A15,Workforce_Data!$G$2:$G$501,B15),0) -> 0.95451181 | G15: =IFERROR(AVERAGEIFS(Workforce_Data!$N$2:$N$501,Workforce_Data!$F$2:$F$501,A15,Workforce_Data!$G$2:$G$501,B15),0) -> 22.777778 | H15: =IFERROR(AVERAGEIFS(Workforce_Data!$AC$2:$AC$501,Workforce_Data!$F$2:$F$501,A15,Workforce_Data!$G$2:$G$501,B15),0) -> 26.166667 | I15: =IFERROR(AVERAGEIFS(Workforce_Data!$AD$2:$AD$501,Workforce_Data!$F$2:$F$501,A15,Workforce_Data!$G$2:$G$501,B15),0) -> 3.3888889 | J15: =COUNTIFS(Workforce_Data!$F$2:$F$501,A15,Workforce_Data!$G$2:$G$501,B15,Workforce_Data!$AD$2:$AD$501,">0") -> 17 | K15: =COUNTIFS(Workforce_Data!$F$2:$F$501,A15,Workforce_Data!$G$2:$G$501,B15,Workforce_Data!$AD$2:$AD$501,"<0") -> 1
... A18: Line-5 | B18: Night | C18: =COUNTIFS(Workforce_Data!$F:$F,$A18,Workforce_Data!$G:$G,$B18) -> 10 | D18: =IFERROR(AVERAGEIFS(Workforce_Data!$W$2:$W$501,Workforce_Data!$F$2:$F$501,A18,Workforce_Data!$G$2:$G$501,B18),0) -> 95.780204 | E18: 100.66501 | F18: =IFERROR(AVERAGEIFS(Workforce_Data!$Z$2:$Z$501,Workforce_Data!$F$2:$F$501,A18,Workforce_Data!$G$2:$G$501,B18),0) -> 0.95147461 | G18: =IFERROR(AVERAGEIFS(Workforce_Data!$N$2:$N$501,Workforce_Data!$F$2:$F$501,A18,Workforce_Data!$G$2:$G$501,B18),0) -> 16.8 | H18: =IFERROR(AVERAGEIFS(Workforce_Data!$AC$2:$AC$501,Workforce_Data!$F$2:$F$501,A18,Workforce_Data!$G$2:$G$501,B18),0) -> 19.7 | I18: =IFERROR(AVERAGEIFS(Workforce_Data!$AD$2:$AD$501,Workforce_Data!$F$2:$F$501,A18,Workforce_Data!$G$2:$G$501,B18),0) -> 2.9 | J18: =COUNTIFS(Workforce_Data!$F$2:$F$501,A18,Workforce_Data!$G$2:$G$501,B18,Workforce_Data!$AD$2:$AD$501,">0") -> 9 | K18: =COUNTIFS(Workforce_Data!$F$2:$F$501,A18,Workforce_Data!$G$2:$G$501,B18,Workforce_Data!$AD$2:$AD$501,"<0") -> 1

Sheet Product_Summary
A1: PRODUCT-LEVEL WORKFORCE ANALYSIS
A3: Product_ID | B3: Product_Name | C3: Records | D3: Avg_Productivity | E3: Benchmark_P75 | F3: Avg_Efficiency | G3: Avg_Present_Workers | H3: Avg_Required_Workers | I3: Avg_Gap | J3: Shortage_Obs | K3: Surplus_Obs
A4: SF-P001 | B4: Corn Flakes | C4: =COUNTIF(Workforce_Data!$D$2:$D$501,A4) -> 2 | D4: =IFERROR(AVERAGEIF(Workforce_Data!$D$2:$D$501,A4,Workforce_Data!$W$2:$W$501),0) -> 110.46372 | E4: 114.84001 | F4: =IFERROR(AVERAGEIF(Workforce_Data!$D$2:$D$501,A4,Workforce_Data!$Z$2:$Z$501),0) -> 0.89862564 | G4: =IFERROR(AVERAGEIF(Workforce_Data!$D$2:$D$501,A4,Workforce_Data!$N$2:$N$501),0) -> 24 | H4: =IFERROR(AVERAGEIF(Workforce_Data!$D$2:$D$501,A4,Workforce_Data!$AC$2:$AC$501),0) -> 27.5 | I4: =IFERROR(AVERAGEIF(Workforce_Data!$D$2:$D$501,A4,Workforce_Data!$AD$2:$AD$501),0) -> 3.5 | J4: =COUNTIFS(Workforce_Data!$D$2:$D$501,A4,Workforce_Data!$AD$2:$AD$501,">0") -> 2 | K4: =COUNTIFS(Workforce_Data!$D$2:$D$501,A4,Workforce_Data!$AD$2:$AD$501,"<0") -> 0
A5: SF-P002 | B5: Corn Flakes | C5: =COUNTIF(Workforce_Data!$D$2:$D$501,A5) -> 1 | D5: =IFERROR(AVERAGEIF(Workforce_Data!$D$2:$D$501,A5,Workforce_Data!$W$2:$W$501),0) -> 98.92905 | E5: 98.92905 | F5: =IFERROR(AVERAGEIF(Workforce_Data!$D$2:$D$501,A5,Workforce_Data!$Z$2:$Z$501),0) -> 0.87560635 | G5: =IFERROR(AVERAGEIF(Workforce_Data!$D$2:$D$501,A5,Workforce_Data!$N$2:$N$501),0) -> 14 | H5: =IFERROR(AVERAGEIF(Workforce_Data!$D$2:$D$501,A5,Workforce_Data!$AC$2:$AC$501),0) -> 16 | I5: =IFERROR(AVERAGEIF(Workforce_Data!$D$2:$D$501,A5,Workforce_Data!$AD$2:$AD$501),0) -> 2 | J5: =COUNTIFS(Workforce_Data!$D$2:$D$501,A5,Workforce_Data!$AD$2:$AD$501,">0") -> 1 | K5: =COUNTIFS(Workforce_Data!$D$2:$D$501,A5,Workforce_Data!$AD$2:$AD$501,"<0") -> 0
A6: SF-P003 | B6: Corn Flakes | C6: =COUNTIF(Workforce_Data!$D$2:$D$501,A6) -> 4 | D6: =IFERROR(AVERAGEIF(Workforce_Data!$D$2:$D$501,A6,Workforce_Data!$W$2:$W$501),0) -> 111.1985 | E6: 114.72125 | F6: =IFERROR(AVERAGEIF(Workforce_Data!$D$2:$D$501,A6,Workforce_Data!$Z$2:$Z$501),0) -> 0.96490789 | G6: =IFERROR(AVERAGEIF(Workforce_Data!$D$2:$D$501,A6,Workforce_Data!$N$2:$N$501),0) -> 20.5 | H6: =IFERROR(AVERAGEIF(Workforce_Data!$D$2:$D$501,A6,Workforce_Data!$AC$2:$AC$501),0) -> 25.25 | I6: =IFERROR(AVERAGEIF(Workforce_Data!$D$2:$D$501,A6,Workforce_Data!$AD$2:$AD$501),0) -> 4.75 | J6: =COUNTIFS(Workforce_Data!$D$2:$D$501,A6,Workforce_Data!$AD$2:$AD$501,">0") -> 4 | K6: =COUNTIFS(Workforce_Data!$D$2:$D$501,A6,Workforce_Data!$AD$2:$AD$501,"<0") -> 0
A7: SF-P004 | B7: Corn Flakes With Honey | C7: =COUNTIF(Workforce_Data!$D$2:$D$501,A7) -> 10 | D7: =IFERROR(AVERAGEIF(Workforce_Data!$D$2:$D$501,A7,Workforce_Data!$W$2:$W$501),0) -> 104.3969 | E7: 111.861 | F7: =IFERROR(AVERAGEIF(Workforce_Data!$D$2:$D$501,A7,Workforce_Data!$Z$2:$Z$501),0) -> 0.92185817 | G7: =IFERROR(AVERAGEIF(Workforce_Data!$D$2:$D$501,A7,Workforce_Data!$N$2:$N$501),0) -> 18.4 | H7: =IFERROR(AVERAGEIF(Workforce_Data!$D$2:$D$501,A7,Workforce_Data!$AC$2:$AC$501),0) -> 20.4 | I7: =IFERROR(AVERAGEIF(Workforce_Data!$D$2:$D$501,A7,Workforce_Data!$AD$2:$AD$501),0) -> 2 | J7: =COUNTIFS(Workforce_Data!$D$2:$D$501,A7,Workforce_Data!$AD$2:$AD$501,">0") -> 8 | K7: =COUNTIFS(Workforce_Data!$D$2:$D$501,A7,Workforce_Data!$AD$2:$AD$501,"<0") -> 0
A8: SF-P005 | B8: Choco Flakes | C8: =COUNTIF(Workforce_Data!$D$2:$D$501,A8) -> 8 | D8: =IFERROR(AVERAGEIF(Workforce_Data!$D$2:$D$501,A8,Workforce_Data!$W$2:$W$501),0) -> 104.70301 | E8: 115.81351 | F8: =IFERROR(AVERAGEIF(Workforce_Data!$D$2:$D$501,A8,Workforce_Data!$Z$2:$Z$501),0) -> 0.91695254 | G8: =IFERROR(AVERAGEIF(Workforce_Data!$D$2:$D$501,A8,Workforce_Data!$N$2:$N$501),0) -> 20.625 | H8: =IFERROR(AVERAGEIF(Workforce_Data!$D$2:$D$501,A8,Workforce_Data!$AC$2:$AC$501),0) -> 24.125 | I8: =IFERROR(AVERAGEIF(Workforce_Data!$D$2:$D$501,A8,Workforce_Data!$AD$2:$AD$501),0) -> 3.5 | J8: =COUNTIFS(Workforce_Data!$D$2:$D$501,A8,Workforce_Data!$AD$2:$AD$501,">0") -> 8 | K8: =COUNTIFS(Workforce_Data!$D$2:$D$501,A8,Workforce_Data!$AD$2:$AD$501,"<0") -> 0
A9: SF-P007 | B9: Oats Flakes | C9: =COUNTIF(Workforce_Data!$D$2:$D$501,A9) -> 3 | D9: =IFERROR(AVERAGEIF(Workforce_Data!$D$2:$D$501,A9,Workforce_Data!$W$2:$W$501),0) -> 102.89812 | E9: 107.16095 | F9: =IFERROR(AVERAGEIF(Workforce_Data!$D$2:$D$501,A9,Workforce_Data!$Z$2:$Z$501),0) -> 0.90418523 | G9: =IFERROR(AVERAGEIF(Workforce_Data!$D$2:$D$501,A9,Workforce_Data!$N$2:$N$501),0) -> 21 | H9: =IFERROR(AVERAGEIF(Workforce_Data!$D$2:$D$501,A9,Workforce_Data!$AC$2:$AC$501),0) -> 23.333333 | I9: =IFERROR(AVERAGEIF(Workforce_Data!$D$2:$D$501,A9,Workforce_Data!$AD$2:$AD$501),0) -> 2.3333333 | J9: =COUNTIFS(Workforce_Data!$D$2:$D$501,A9,Workforce_Data!$AD$2:$AD$501,">0") -> 3 | K9: =COUNTIFS(Workforce_Data!$D$2:$D$501,A9,Workforce_Data!$AD$2:$AD$501,"<0") -> 0
A10: SF-P008 | B10: Jumbo Oats | C10: =COUNTIF(Workforce_Data!$D$2:$D$501,A10) -> 4 | D10: =IFERROR(AVERAGEIF(Workforce_Data!$D$2:$D$501,A10,Workforce_Data!$W$2:$W$501),0) -> 102.54599 | E10: 109.52846 | F10: =IFERROR(AVERAGEIF(Workforce_Data!$D$2:$D$501,A10,Workforce_Data!$Z$2:$Z$501),0) -> 0.91399223 | G10: =IFERROR(AVERAGEIF(Workforce_Data!$D$2:$D$501,A10,Workforce_Data!$N$2:$N$501),0) -> 20.25 | H10: =IFERROR(AVERAGEIF(Workforce_Data!$D$2:$D$501,A10,Workforce_Data!$AC$2:$AC$501),0) -> 22.75 | I10: =IFERROR(AVERAGEIF(Workforce_Data!$D$2:$D$501,A10,Workforce_Data!$AD$2:$AD$501),0) -> 2.5 | J10: =COUNTIFS(Workforce_Data!$D$2:$D$501,A10,Workforce_Data!$AD$2:$AD$501,">0") -> 4 | K10: =COUNTIFS(Workforce_Data!$D$2:$D$501,A10,Workforce_Data!$AD$2:$AD$501,"<0") -> 0
A11: SF-P009 | B11: Mix Fruit Muesli | C11: =COUNTIF(Workforce_Data!$D$2:$D$501,A11) -> 4 | D11: =IFERROR(AVERAGEIF(Workforce_Data!$D$2:$D$501,A11,Workforce_Data!$W$2:$W$501),0) -> 87.648499 | E11: 88.314968 | F11: =IFERROR(AVERAGEIF(Workforce_Data!$D$2:$D$501,A11,Workforce_Data!$Z$2:$Z$501),0) -> 0.76682558 | G11: =IFERROR(AVERAGEIF(Workforce_Data!$D$2:$D$501,A11,Workforce_Data!$N$2:$N$501),0) -> 19.75 | H11: =IFERROR(AVERAGEIF(Workforce_Data!$D$2:$D$501,A11,Workforce_Data!$AC$2:$AC$501),0) -> 17.5 | I11: =IFERROR(AVERAGEIF(Workforce_Data!$D$2:$D$501,A11,Workforce_Data!$AD$2:$AD$501),0) -> -2.25 | J11: =COUNTIFS(Workforce_Data!$D$2:$D$501,A11,Workforce_Data!$AD$2:$AD$501,">0") -> 0 | K11: =COUNTIFS(Workforce_Data!$D$2:$D$501,A11,Workforce_Data!$AD$2:$AD$501,"<0") -> 4
A12: SF-P010 | B12: Muesli | C12: =COUNTIF(Workforce_Data!$D$2:$D$501,A12) -> 10 | D12: =IFERROR(AVERAGEIF(Workforce_Data!$D$2:$D$501,A12,Workforce_Data!$W$2:$W$501),0) -> 84.886067 | E12: 87.748655 | F12: =IFERROR(AVERAGEIF(Workforce_Data!$D$2:$D$501,A12,Workforce_Data!$Z$2:$Z$501),0) -> 0.74103283 | G12: =IFERROR(AVERAGEIF(Workforce_Data!$D$2:$D$501,A12,Workforce_Data!$N$2:$N$501),0) -> 20.9 | H12: =IFERROR(AVERAGEIF(Workforce_Data!$D$2:$D$501,A12,Workforce_Data!$AC$2:$AC$501),0) -> 19.4 | I12: =IFERROR(AVERAGEIF(Workforce_Data!$D$2:$D$501,A12,Workforce_Data!$AD$2:$AD$501),0) -> -1.5 | J12: =COUNTIFS(Workforce_Data!$D$2:$D$501,A12,Workforce_Data!$AD$2:$AD$501,">0") -> 0 | K12: =COUNTIFS(Workforce_Data!$D$2:$D$501,A12,Workforce_Data!$AD$2:$AD$501,"<0") -> 10
A13: SF-P011 | B13: Wheat Crispy | C13: =COUNTIF(Workforce_Data!$D$2:$D$501,A13) -> 5 | D13: =IFERROR(AVERAGEIF(Workforce_Data!$D$2:$D$501,A13,Workforce_Data!$W$2:$W$501),0) -> 111.86186 | E13: 118.44929 | F13: =IFERROR(AVERAGEIF(Workforce_Data!$D$2:$D$501,A13,Workforce_Data!$Z$2:$Z$501),0) -> 0.99398796 | G13: =IFERROR(AVERAGEIF(Workforce_Data!$D$2:$D$501,A13,Workforce_Data!$N$2:$N$501),0) -> 20.2 | H13: =IFERROR(AVERAGEIF(Workforce_Data!$D$2:$D$501,A13,Workforce_Data!$AC$2:$AC$501),0) -> 24 | I13: =IFERROR(AVERAGEIF(Workforce_Data!$D$2:$D$501,A13,Workforce_Data!$AD$2:$AD$501),0) -> 3.8 | J13: =COUNTIFS(Workforce_Data!$D$2:$D$501,A13,Workforce_Data!$AD$2:$AD$501,">0") -> 5 | K13: =COUNTIFS(Workforce_Data!$D$2:$D$501,A13,Workforce_Data!$AD$2:$AD$501,"<0") -> 0
A14: SF-P012 | B14: Rice Crispy | C14: =COUNTIF(Workforce_Data!$D$2:$D$501,A14) -> 3 | D14: =IFERROR(AVERAGEIF(Workforce_Data!$D$2:$D$501,A14,Workforce_Data!$W$2:$W$501),0) -> 113.44462 | E14: 114.4209 | F14: =IFERROR(AVERAGEIF(Workforce_Data!$D$2:$D$501,A14,Workforce_Data!$Z$2:$Z$501),0) -> 0.99621867 | G14: =IFERROR(AVERAGEIF(Workforce_Data!$D$2:$D$501,A14,Workforce_Data!$N$2:$N$501),0) -> 21.666667 | H14: =IFERROR(AVERAGEIF(Workforce_Data!$D$2:$D$501,A14,Workforce_Data!$AC$2:$AC$501),0) -> 24.666667 | I14: =IFERROR(AVERAGEIF(Workforce_Data!$D$2:$D$501,A14,Workforce_Data!$AD$2:$AD$501),0) -> 3 | J14: =COUNTIFS(Workforce_Data!$D$2:$D$501,A14,Workforce_Data!$AD$2:$AD$501,">0") -> 3 | K14: =COUNTIFS(Workforce_Data!$D$2:$D$501,A14,Workforce_Data!$AD$2:$AD$501,"<0") -> 0
A15: SF-P013 | B15: Cocoa Rice Crispy | C15: =COUNTIF(Workforce_Data!$D$2:$D$501,A15) -> 5 | D15: =IFERROR(AVERAGEIF(Workforce_Data!$D$2:$D$501,A15,Workforce_Data!$W$2:$W$501),0) -> 108.77716 | E15: 110.52124 | F15: =IFERROR(AVERAGEIF(Workforce_Data!$D$2:$D$501,A15,Workforce_Data!$Z$2:$Z$501),0) -> 0.96932783 | G15: =IFERROR(AVERAGEIF(Workforce_Data!$D$2:$D$501,A15,Workforce_Data!$N$2:$N$501),0) -> 18 | H15: =IFERROR(AVERAGEIF(Workforce_Data!$D$2:$D$501,A15,Workforce_Data!$AC$2:$AC$501),0) -> 21.6 | I15: =IFERROR(AVERAGEIF(Workforce_Data!$D$2:$D$501,A15,Workforce_Data!$AD$2:$AD$501),0) -> 3.6 | J15: =COUNTIFS(Workforce_Data!$D$2:$D$501,A15,Workforce_Data!$AD$2:$AD$501,">0") -> 5 | K15: =COUNTIFS(Workforce_Data!$D$2:$D$501,A15,Workforce_Data!$AD$2:$AD$501,"<0") -> 0
... A102: SF-P100 | B102: Granola - Variant 5 | C102: =COUNTIF(Workforce_Data!$D$2:$D$501,A102) -> 5 | D102: =IFERROR(AVERAGEIF(Workforce_Data!$D$2:$D$501,A102,Workforce_Data!$W$2:$W$501),0) -> 73.98424 | E102: 75.620369 | F102: =IFERROR(AVERAGEIF(Workforce_Data!$D$2:$D$501,A102,Workforce_Data!$Z$2:$Z$501),0) -> 0.65529079 | G102: =IFERROR(AVERAGEIF(Workforce_Data!$D$2:$D$501,A102,Workforce_Data!$N$2:$N$501),0) -> 21 | H102: =IFERROR(AVERAGEIF(Workforce_Data!$D$2:$D$501,A102,Workforce_Data!$AC$2:$AC$501),0) -> 17.2 | I102: =IFERROR(AVERAGEIF(Workforce_Data!$D$2:$D$501,A102,Workforce_Data!$AD$2:$AD$501),0) -> -3.8 | J102: =COUNTIFS(Workforce_Data!$D$2:$D$501,A102,Workforce_Data!$AD$2:$AD$501,">0") -> 0 | K102: =COUNTIFS(Workforce_Data!$D$2:$D$501,A102,Workforce_Data!$AD$2:$AD$501,"<0") -> 5

Sheet Manpower_Calculator
A1: MANPOWER PLANNING CALCULATOR | H1: SF-P001 | I1: Line-1 | J1: Afternoon
H2: SF-P002 | I2: Line-2 | J2: Morning
A3: INPUTS | B3: Values | D3: CALCULATED OUTPUT | H3: SF-P003 | I3: Line-3 | J3: Night
A4: Product ID | B4: SF-P068 | D4: Benchmark Productivity (Units/Labour-Hour) | E4: =SUMIFS($D:$D,$A:$A,$B$5,$B:$B,$B$6) -> 118.01657 | H4: SF-P004 | I4: Line-4
A5: Production Line | B5: Line-5 | D5: Effective Hours / Worker | E5: =MAX(0.1,B8-B9/60) -> 7.5 | H5: SF-P005 | I5: Line-5
A6: Shift | B6: Morning | D6: Required Labour Hours | E6: =IFERROR(B7/E4,0) -> 84.733868 | H6: SF-P007
A7: Planned Good Quantity (Units) | B7: 10000 | D7: REQUIRED WORKERS | E7: =CEILING(E6/E5,1) -> 12 | H7: SF-P008
A8: Shift Hours | B8: 8 | H8: SF-P009
A9: Planned Downtime (Minutes) | B9: 30 | H9: SF-P010
H10: SF-P011
H11: SF-P012
H12: SF-P013
A13: BENCHMARK DATA — LINE + SHIFT | H13: SF-P014
A14: Production Line | B14: Shift | C14: Records | D14: Benchmark Productivity | E14: Avg Downtime Minutes | F14: Key | H14: SF-P015
A15: Line-1 | B15: Afternoon | C15: 38 | D15: 112.98348 | E15: 32.184211 | F15: Line-1|Afternoon | H15: SF-P016
A16: Line-1 | B16: Morning | C16: 53 | D16: 115.18556 | E16: 34.283019 | F16: Line-1|Morning | H16: SF-P017
A17: Line-1 | B17: Night | C17: 17 | D17: 99.399923 | E17: 33.470588 | F17: Line-1|Night | H17: SF-P018
A18: Line-2 | B18: Afternoon | C18: 37 | D18: 118.40848 | E18: 35.594595 | F18: Line-2|Afternoon | H18: SF-P019
A19: Line-2 | B19: Morning | C19: 44 | D19: 124.7824 | E19: 31.795455 | F19: Line-2|Morning | H19: SF-P020
A20: Line-2 | B20: Night | C20: 16 | D20: 107.36289 | E20: 38.6875 | F20: Line-2|Night | H20: SF-P021
A21: Line-3 | B21: Afternoon | C21: 43 | D21: 108.32817 | E21: 31.813953 | F21: Line-3|Afternoon | H21: SF-P022
A22: Line-3 | B22: Morning | C22: 52 | D22: 109.38855 | E22: 31.230769 | F22: Line-3|Morning | H22: SF-P023
A23: Line-4 | B23: Afternoon | C23: 28 | D23: 120.8175 | E23: 25.5 | F23: Line-4|Afternoon
A24: Line-4 | B24: Morning | C24: 34 | D24: 128.22014 | E24: 33.941176 | F24: Line-4|Morning
A25: Line-4 | B25: Night | C25: 18 | D25: 114.65795 | E25: 28.166667 | F25: Line-4|Night
A26: Line-5 | B26: Afternoon | C26: 33 | D26: 114.15637 | E26: 30.030303 | F26: Line-5|Afternoon
A27: Line-5 | B27: Morning | C27: 58 | D27: 118.01657 | E27: 34.5 | F27: Line-5|Morning
A28: Line-5 | B28: Night | C28: 10 | D28: 100.66501 | E28: 34.4 | F28: Line-5|Night
H29: SF-P024
H30: SF-P025
A31: HOW TO USE | H31: SF-P026
A32: • Enter Product, Line, Shift, planned good quantity, shift hours and planned downtime. | H32: SF-P027
A33: • Benchmark = historical 75th percentile productivity for the selected Line + Shift. | H33: SF-P028
A34: • Required Labour Hours = Planned Good Quantity ÷ Benchmark Productivity. | H34: SF-P029
A35: • Required Workers = Required Labour Hours ÷ Effective Hours per Worker, rounded up. | H35: SF-P030
A36: • Available/current workers are intentionally NOT an input. | H36: SF-P031
A37: • Current data is illustrative/synthetic. | H37: SF-P032
H38: SF-P033
H39: SF-P034
H40: SF-P035
...

Sheet Lists
A1: SF-P001 | B1: Corn Flakes | D1: Line-1 | E1: Afternoon
A2: SF-P002 | B2: Corn Flakes | D2: Line-2 | E2: Morning
A3: SF-P003 | B3: Corn Flakes | D3: Line-3 | E3: Night
A4: SF-P004 | B4: Corn Flakes With Honey | D4: Line-4
A5: SF-P005 | B5: Choco Flakes | D5: Line-5
A6: SF-P007 | B6: Oats Flakes
A7: SF-P008 | B7: Jumbo Oats
A8: SF-P009 | B8: Mix Fruit Muesli
A9: SF-P010 | B9: Muesli
A10: SF-P011 | B10: Wheat Crispy
A11: SF-P012 | B11: Rice Crispy
A12: SF-P013 | B12: Cocoa Rice Crispy
A13: SF-P014 | B13: Fruit Ball
A14: SF-P015 | B14: Coated Crispy Choco Balls
A15: SF-P016 | B15: Instant Breakfast Cereal
A16: SF-P017 | B16: Fruit Rings
A17: SF-P018 | B17: Honey Ball
... A99: SF-P100 | B99: Granola - Variant 5
